Workbook

Sheet source_cprd_aurum
A1: description | B1: PSSRU cost | C1: Unit type | D1: Source in PSSRU | E1: Band (source/assumption) | F1: category | G1: Expected mean duration consultation by Lindsey | H1: unit_cost_encounter | I1: Notes
A2: Associate Practitioner - Nurse | B2: 47 | C2: hourly | D2: Table 9.2.1 “Annual and unit costs for qualified nurses” – Cost per working hour (without qualification) | E2: Assumed Band 5 from Table 11.2.1 – “Nurse” | F2: Nurse | G2: 15 | H2: =(B2/60)*G2 -> 11.75
A3: Appointments Clerk | B3: 30238 | C3: annual | D3: Table 12.2.5 “Mean annual basic pay per FTE for NHS staff groups” – Admin & Clerical | F3: Admin | G3: 1 | H3: =(B3/((52*37.5)-217.5-60)/60)*G3 -> 0.30132536 | I3: based on 52 weeks, 37.5hrs pw, annual leave (217.5, based on 29 days which corresponds to NHS employees with 5 to 10 years of service) and bank holidays (8 days)
A4: Audit Manager | B4: 62428 | C4: annual | D4: Table 12.2.5 “Mean annual basic pay per FTE for NHS staff groups” – Managers | F4: Admin | G4: 1 | H4: =(B4/((52*37.5)-217.5-60)/60)*G4 -> 0.62210264 | I4: based on 52 weeks, 37.5hrs pw, annual leave (217.5, based on 29 days which corresponds to NHS employees with 5 to 10 years of service) and bank holidays (8 days)
A5: Art Therapist | B5: 68 | C5: hourly | D5: Table 8.2.1 “Annual and unit costs for community-based scientific & professional staff” – Cost per working hour (without qualification) | E5: Table 8.1 “Agenda for Change bands for scientific & professional staff” – assumed Band 7 Arts Therapist | F5: AHP | G5: 20 | H5: =(B5/60)*G5 -> 22.666667
A6: Art Therapist Consultant | B6: 106 | C6: hourly | D6: Table 8.2.1 “Annual and unit costs for community-based scientific & professional staff” – Cost per working hour (without qualification) | E6: Table 8.1 “Agenda for Change bands for scientific & professional staff” – assumed Band 8c Arts therapies consultant | F6: AHP | G6: 15 | H6: =(B6/60)*G6 -> 26.5
A7: Art Therapist Manager | B7: 106 | C7: hourly | D7: Table 8.2.1 “Annual and unit costs for community-based scientific & professional staff” – Cost per working hour (without qualification) | E7: Table 8.1 “Agenda for Change bands for scientific & professional staff” – assumed Band 8c Head of arts therapies | F7: AHP | G7: 20 | H7: =(B7/60)*G7 -> 35.333333
A8: Art Therapist Specialist Practitioner | B8: 77 | C8: hourly | D8: Table 8.2.1 “Annual and unit costs for community-based scientific & professional staff” – Cost per working hour (without qualification) | E8: Table 8.1 “Agenda for Change bands for scientific & professional staff” – assumed Band 8a Arts Therapist principal | F8: AHP | G8: 15 | H8: =(B8/60)*G8 -> 19.25
A9: Porter | B9: 30238 | C9: annual | D9: Table 12.2.5 “Mean annual basic pay per FTE for NHS staff groups” – Admin & Clerical | F9: Non-registered other | G9: 2 | H9: =(B9/((52*37.5)-217.5-60)/60)*G9 -> 0.60265072 | I9: based on 52 weeks, 37.5hrs pw, annual leave (217.5, based on 29 days which corresponds to NHS employees with 5 to 10 years of service) and bank holidays (8 days)
A10: Healthcare Science Assistant | B10: 36000 | C10: annual | D10: Table 12.2.1 “Mean annual basic pay per FTE for non‑medical occupational groupings” – Healthcare scientists | F10: Non-registered other | G10: 5 | H10: =(B10/((52*37.5)-217.5-60)/60)*G10 -> 1.793722 | I10: based on 52 weeks, 37.5hrs pw, annual leave (217.5, based on 29 days which corresponds to NHS employees with 5 to 10 years of service) and bank holidays (8 days)
A11: Officer | B11: 30238 | C11: annual | D11: Table 12.2.5 “Mean annual basic pay per FTE for NHS staff groups” – Admin & Clerical | F11: Non-registered other | G11: 5 | H11: =(B11/((52*37.5)-217.5-60)/60)*G11 -> 1.5066268 | I11: based on 52 weeks, 37.5hrs pw, annual leave (217.5, based on 29 days which corresponds to NHS employees with 5 to 10 years of service) and bank holidays (8 days) / GF assigned category and duration
A12: Associate Practitioner - General Practitioner | B12: 3.7 | C12: per minute | D12: Table 9.4.2 “Unit costs for a GP” – Cost per minute of patient contact (without qualification) | F12: GP | G12: 15 | H12: =G12*B12 -> 55.5
A13: Director of Nursing | B13: 90859 | C13: annual | D13: Table 12.2.5 “Mean annual basic pay per FTE for NHS staff groups” – Senior managers | F13: Nurse | G13: 15 | H13: =(B13/((52*37.5)-217.5-60)/60)*G13 -> 13.581315 | I13: based on 52 weeks, 37.5hrs pw, annual leave (217.5, based on 29 days which corresponds to NHS employees with 5 to 10 years of service) and bank holidays (8 days)
A14: Student Technician | B14: 27214 | C14: annual | D14: Table 12.2.1 “Mean annual basic pay per FTE for non‑medical occupational groupings” – Nursing, midwifery and health visiting learners | F14: Non-registered other | G14: 5 | H14: =(B14/((52*37.5)-217.5-60)/60)*G14 -> 1.3559542 | I14: based on 52 weeks, 37.5hrs pw, annual leave (217.5, based on 29 days which corresponds to NHS employees with 5 to 10 years of service) and bank holidays (8 days)
A15: Asst. Clinical Medical Officer | B15: 3.7 | C15: per minute | D15: Table 9.4.2 “Unit costs for a GP” – Cost per minute of patient contact (without qualification) | F15: Medic non-GP | G15: 15 | H15: =G15*B15 -> 55.5 | I15: GF assigned category
A16: Audiologist | B16: 44 | C16: hourly | D16: Table 8.2.1 “Annual and unit costs for community-based scientific & professional staff” – Cost per working hour (without qualification) | E16: Table 8.1 “Agenda for Change bands for scientific & professional staff” – assumed Band 5 Audiologist | F16: AHP | G16: 20 | H16: =(B16/60)*G16 -> 14.666667
A17: Availability Monitor | B17: 30238 | C17: annual | D17: Table 12.2.5 “Mean annual basic pay per FTE for NHS staff groups” – Admin & Clerical | F17: Admin | G17: 1 | H17: =(B17/((52*37.5)-217.5-60)/60)*G17 -> 0.30132536 | I17: based on 52 weeks, 37.5hrs pw, annual leave (217.5, based on 29 days which corresponds to NHS employees with 5 to 10 years of service) and bank holidays (8 days)
A18: Clinical Application Administrator | B18: 30238 | C18: annual | D18: Table 12.2.5 “Mean annual basic pay per FTE for NHS staff groups” – Admin & Clerical | F18: Admin | G18: 1 | H18: =(B18/((52*37.5)-217.5-60)/60)*G18 -> 0.30132536 | I18: based on 52 weeks, 37.5hrs pw, annual leave (217.5, based on 29 days which corresponds to NHS employees with 5 to 10 years of service) and bank holidays (8 days)
A19: Biomedical Scientist | B19: 44 | C19: hourly | D19: Table 8.2.1 “Annual and unit costs for community-based scientific & professional staff” – Cost per working hour (without qualification) | E19: Table 8.1 “Agenda for Change bands for scientific & professional staff” – assumed Band 5 Biomedical Scientist | F19: AHP | G19: 20 | H19: =(B19/60)*G19 -> 14.666667
A20: Caldicott Guardian | B20: 90859 | C20: annual | D20: Table 12.2.5 “Mean annual basic pay per FTE for NHS staff groups” – Senior managers | F20: Medic non-GP | G20: 5 | H20: =(B20/((52*37.5)-217.5-60)/60)*G20 -> 4.5271051 | I20: based on 52 weeks, 37.5hrs pw, annual leave (217.5, based on 29 days which corresponds to NHS employees with 5 to 10 years of service) and bank holidays (8 days) / GF assigned category and duration
A21: Clinical Coder | B21: 30238 | C21: annual | D21: Table 12.2.5 “Mean annual basic pay per FTE for NHS staff groups” – Admin & Clerical | F21: Admin | G21: 1 | H21: =(B21/((52*37.5)-217.5-60)/60)*G21 -> 0.30132536 | I21: based on 52 weeks, 37.5hrs pw, annual leave (217.5, based on 29 days which corresponds to NHS employees with 5 to 10 years of service) and bank holidays (8 days)
A22: Child Protection worker | B22: 48 | C22: hourly | D22: Table 10.1.1 “Costs and unit estimations for a social worker (adult services)” – Cost per working hour (without qualification) | E22: Assumed match to Social worker (adult services) | F22: Social | G22: 5 | H22: =(B22/60)*G22 -> 4 | I22: GF assigned duration
A23: Chiropodist/Podiatrist | B23: 44 | C23: hourly | D23: Table 8.2.1 “Annual and unit costs for community-based scientific & professional staff” – Cost per working hour (without qualification) | E23: Table 12.3.4 “Agenda for Change Bands for Chiropodists/Podiatrists” – Band 5 Podiatrist | F23: AHP | G23: 20 | H23: =(B23/60)*G23 -> 14.666667
A24: Chiropodist/Podiatrist Consultant | B24: 106 | C24: hourly | D24: Table 8.2.1 “Annual and unit costs for community-based scientific & professional staff” – Cost per working hour (without qualification) | E24: Table 12.3.4 “Agenda for Change Bands for Chiropodists/Podiatrists” – Band 8c Podiatric consultant | F24: AHP | G24: 15 | H24: =(B24/60)*G24 -> 26.5
A25: Chiropodist/Podiatrist Manager | B25: 77 | C25: hourly | D25: Table 8.2.1 “Annual and unit costs for community-based scientific & professional staff” – Cost per working hour (without qualification) | E25: Table 12.3.4 “Agenda for Change Bands for Chiropodists/Podiatrists” – Band 8a Podiatrist principal | F25: AHP | G25: 15 | H25: =(B25/60)*G25 -> 19.25
A26: Chiropodist/Podiatrist Specialist Practitioner | B26: 57 | C26: hourly | D26: Table 8.2.1 “Annual and unit costs for community-based scientific & professional staff” – Cost per working hour (without qualification) | E26: Table 12.3.4 “Agenda for Change Bands for Chiropodists/Podiatrists” – Band 6 Podiatrist specialist | F26: AHP | G26: 15 | H26: =(B26/60)*G26 -> 14.25
A27: Desktop Support Administrator | B27: 30238 | C27: annual | D27: Table 12.2.5 “Mean annual basic pay per FTE for NHS staff groups” – Admin & Clerical | F27: Admin | G27: 1 | H27: =(B27/((52*37.5)-217.5-60)/60)*G27 -> 0.30132536 | I27: based on 52 weeks, 37.5hrs pw, annual leave (217.5, based on 29 days which corresponds to NHS employees with 5 to 10 years of service) and bank holidays (8 days)
A28: Desktop Support Technician | B28: 30238 | C28: annual | D28: Table 12.2.5 “Mean annual basic pay per FTE for NHS staff groups” – Admin & Clerical | F28: Admin | G28: 1 | H28: =(B28/((52*37.5)-217.5-60)/60)*G28 -> 0.30132536 | I28: based on 52 weeks, 37.5hrs pw, annual leave (217.5, based on 29 days which corresponds to NHS employees with 5 to 10 years of service) and bank holidays (8 days)
A29: System Worker | B29: 39 | C29: hourly | D29: Table 8.2.1 “Annual and unit costs for community-based scientific & professional staff” – Cost per working hour (without qualification) | E29: Table 8.1 “Agenda for Change bands for scientific & professional staff” – assumed Band 4 System Worker | F29: Non-registered other | G29: 5 | H29: =(B29/60)*G29 -> 3.25 | I29: GF assigned category and duration
A30: Finance Director | B30: 90859 | C30: annual | D30: Table 12.2.5 “Mean annual basic pay per FTE for NHS staff groups” – Senior managers | F30: Admin | G30: 1 | H30: =(B30/((52*37.5)-217.5-60)/60)*G30 -> 0.90542103 | I30: based on 52 weeks, 37.5hrs pw, annual leave (217.5, based on 29 days which corresponds to NHS employees with 5 to 10 years of service) and bank holidays (8 days)
A31: Clinical Director | B31: 62428 | C31: annual | D31: Table 12.2.5 “Mean annual basic pay per FTE for NHS staff groups” – Managers | F31: Medic non-GP | G31: 5 | H31: =(B31/((52*37.5)-217.5-60)/60)*G31 -> 3.1105132 | I31: based on 52 weeks, 37.5hrs pw, annual leave (217.5, based on 29 days which corresponds to NHS employees with 5 to 10 years of service) and bank holidays (8 days) / GF assigned category
A32: Clinical Director - Medical | B32: 3.7 | C32: per minute | D32: Table 9.4.2 “Unit costs for a GP” – Cost per minute of patient contact (without qualification) | F32: Medic non-GP | G32: 15 | H32: =G32*B32 -> 55.5
A33: Clinical Medical Officer | B33: 3.7 | C33: per minute | D33: Table 9.4.2 “Unit costs for a GP” – Cost per minute of patient contact (without qualification) | F33: Medic non-GP | G33: 15 | H33: =G33*B33 -> 55.5
A34: Technician - Additional Clinical Services | B34: 30238 | C34: annual | D34: Table 12.2.5 “Mean annual basic pay per FTE for NHS staff groups” – Admin & Clerical | F34: Non-registered other | G34: 5 | H34: =(B34/((52*37.5)-217.5-60)/60)*G34 -> 1.5066268 | I34: based on 52 weeks, 37.5hrs pw, annual leave (217.5, based on 29 days which corresponds to NHS employees with 5 to 10 years of service) and bank holidays (8 days)
A35: Helpdesk Administrator | B35: 30238 | C35: annual | D35: Table 12.2.5 “Mean annual basic pay per FTE for NHS staff groups” – Admin & Clerical | F35: Admin | G35: 1 | H35: =(B35/((52*37.5)-217.5-60)/60)*G35 -> 0.30132536 | I35: based on 52 weeks, 37.5hrs pw, annual leave (217.5, based on 29 days which corresponds to NHS employees with 5 to 10 years of service) and bank holidays (8 days)
A36: Helpdesk Technician | B36: 30238 | C36: annual | D36: Table 12.2.5 “Mean annual basic pay per FTE for NHS staff groups” – Admin & Clerical | F36: Admin | G36: 1 | H36: =(B36/((52*37.5)-217.5-60)/60)*G36 -> 0.30132536 | I36: based on 52 weeks, 37.5hrs pw, annual leave (217.5, based on 29 days which corresponds to NHS employees with 5 to 10 years of service) and bank holidays (8 days)
A37: Modern Matron | B37: 77 | C37: hourly | D37: Table 9.2.1 “Annual and unit costs for qualified nurses” – Cost per working hour (without qualification) | E37: Band 8a from Table 11.2.1 “Agenda for Change (AfC) bands for hospital-based nurses” – mapped title | F37: Nurse | G37: 15 | H37: =(B37/60)*G37 -> 19.25
A38: Nurse Consultant | B38: 105 | C38: hourly | D38: Table 9.2.1 “Annual and unit costs for qualified nurses” – Cost per working hour (without qualification) | E38: Band 8c from Table 11.2.1 “Agenda for Change (AfC) bands for hospital-based nurses” – mapped title | F38: Nurse | G38: 15 | H38: =(B38/60)*G38 -> 26.25
A39: Clinical Assistant | B39: 22984 | C39: annual | D39: Table 12.2.1 “Mean annual basic pay per FTE for non‑medical occupational groupings” – Healthcare assistants and other support staff | F39: Non-registered other | G39: 10 | H39: =(B39/((52*37.5)-217.5-60)/60)*G39 -> 2.2903837 | I39: based on 52 weeks, 37.5hrs pw, annual leave (217.5, based on 29 days which corresponds to NHS employees with 5 to 10 years of service) and bank holidays (8 days)
A40: Information Officer | B40: 30238 | C40: annual | D40: Table 12.2.5 “Mean annual basic pay per FTE for NHS staff groups” – Admin & Clerical | F40: Admin | G40: 1 | H40: =(B40/((52*37.5)-217.5-60)/60)*G40 -> 0.30132536 | I40: based on 52 weeks, 37.5hrs pw, annual leave (217.5, based on 29 days which corresponds to NHS employees with 5 to 10 years of service) and bank holidays (8 days)
...

Sheet omop_standard
A1: specialty_concept_id | B1: concept_name | C1: PSSRU cost | D1: Unit type | E1: Source in PSSRU | F1: Band (source/assumption) | G1: category | H1: Expected mean duration consultation by Lindsey | I1: unit_cost_encounter | J1: Notes
A2: 38004446 | B2: General Practice | C2: 3.7 | D2: per minute | E2: Table 9.4.2 “Unit costs for a GP” – Cost per minute of patient contact (without qualification) | G2: GP | H2: 15 | I2: =H2*C2 -> 55.5
A3: 38004376 | B3: Community Health Nurse Practitioner | C3: 3.7 | D3: per minute | E3: Table 9.4.2 “Unit costs for a GP” – Cost per minute of patient contact (without qualification) | G3: Non-registered other | H3: 20 | I3: =H3*C3 -> 74
A4: 38003794 | B4: Specialist | C4: 3.7 | D4: per minute | E4: Table 9.4.2 “Unit costs for a GP” – Cost per minute of patient contact (without qualification) | G4: Medic non-GP | H4: 15 | I4: =H4*C4 -> 55.5
A5: 38003760 | B5: Registered School Nurse | C5: 39 | D5: hourly | E5: Table 9.2.1 “Annual and unit costs for qualified nurses” – Cost per working hour (without qualification) | F5: Band 4 from Table 11.2.1 “Agenda for Change (AfC) bands for hospital-based nurses” – mapped title | G5: Non-registered other | H5: 20 | I5: =(C5/60)*H5 -> 13
A6: 0 | B6: No matching concept | C6: 44 | D6: hourly | E6: Table 8.2.1 “Annual and unit costs for community-based scientific & professional staff” – Cost per working hour (without qualification) | F6: Band 5 - assumed as a mid range mid-range NHS contact that isn’t GP/consultant level or purely Admin | G6: Uncategorised | H6: 10 | I6: =(C6/60)*H6 -> 7.3333333 | J6: i.e., in athena but no standard concept
A7: 38004056 | B7: Physical Hand Therapist | C7: 44 | D7: hourly | E7: Table 8.2.1 “Annual and unit costs for community-based scientific & professional staff” – Cost per working hour (without qualification) | F7: Table 12.3.1 “Agenda for Change Bands for Physiotherapists” – Band 5 Physiotherapist | G7: AHP | H7: 20 | I7: =(C7/60)*H7 -> 14.666667
A8: 38003696 | B8: Paramedic | C8: 44 | D8: hourly | E8: Table 8.2.1 “Annual and unit costs for community-based scientific & professional staff” – Cost per working hour (without qualification) | F8: Table 8.1 “Agenda for Change bands for scientific & professional staff” – assumed Band 5 Paramedic (treated as AHP) | G8: AHP | H8: 20 | I8: =(C8/60)*H8 -> 14.666667
A9: 38004030 | B9: Podiatrist | C9: 44 | D9: hourly | E9: Table 8.2.1 “Annual and unit costs for community-based scientific & professional staff” – Cost per working hour (without qualification) | F9: Table 12.3.4 “Agenda for Change Bands for Chiropodists/Podiatrists” – Band 5 Podiatrist | G9: AHP | H9: 20 | I9: =(C9/60)*H9 -> 14.666667
A10: 38003627 | B10: Professional Behavioral Health Counselor | C10: 44 | D10: hourly | E10: Table 8.2.1 “Annual and unit costs for community-based scientific & professional staff” – Cost per working hour (without qualification) | F10: Table 12.3.5 “Agenda for Change Bands for Psychologists” – Band 5 Counsellor (entry level) | G10: Non-registered other | H10: 20 | I10: =(C10/60)*H10 -> 14.666667
A11: 38003690 | B11: Registered Dietitian | C11: 44 | D11: hourly | E11: Table 8.2.1 “Annual and unit costs for community-based scientific & professional staff” – Cost per working hour (without qualification) | F11: Table 8.1 “Agenda for Change bands for scientific & professional staff” – assumed Band 5 Dietitian | G11: AHP | H11: 20 | I11: =(C11/60)*H11 -> 14.666667
A12: 38004176 | B12: Radiography Technologist | C12: 44 | D12: hourly | E12: Table 8.2.1 “Annual and unit costs for community-based scientific & professional staff” – Cost per working hour (without qualification) | F12: Table 8.1 “Agenda for Change bands for scientific & professional staff” – assumed Band 5 Radiographer | G12: AHP | H12: 20 | I12: =(C12/60)*H12 -> 14.666667
A13: 38003625 | B13: Mental Health Counselor | C13: 44 | D13: hourly | E13: Table 8.2.1 “Annual and unit costs for community-based scientific & professional staff” – Cost per working hour (without qualification) | F13: Table 12.3.5 “Agenda for Change Bands for Psychologists” – Band 5 Counsellor (entry level) | G13: Non-registered other | H13: 20 | I13: =(C13/60)*H13 -> 14.666667
B14: NA | C14: 44 | D14: hourly | E14: Table 8.2.1 “Annual and unit costs for community-based scientific & professional staff” – Cost per working hour (without qualification) | F14: Band 5 - assumed as a mid range mid-range NHS contact that isn’t GP/consultant level or purely Admin | G14: Missing | H14: 10 | I14: =(C14/60)*H14 -> 7.3333333 | J14: NA (i.e., not in any ATHENA vocabularies at time of mapping)
A15: 38003722 | B15: Registered Community Health Nurse | C15: 47 | D15: hourly | E15: Table 9.2.1 “Annual and unit costs for qualified nurses” – Cost per working hour (without qualification) | F15: Band 5 from Table 11.2.1 “Agenda for Change (AfC) bands for hospital-based nurses” – mapped title | G15: Nurse | H15: 20 | I15: =(C15/60)*H15 -> 15.666667
A16: 38003716 | B16: Registered Nurse | C16: 47 | D16: hourly | E16: Table 9.2.1 “Annual and unit costs for qualified nurses” – Cost per working hour (without qualification) | F16: Band 5 from Table 11.2.1 “Agenda for Change (AfC) bands for hospital-based nurses” – mapped title | G16: Nurse | H16: 20 | I16: =(C16/60)*H16 -> 15.666667
A17: 38003731 | B17: Registered General Practice Nurse | C17: 47 | D17: hourly | E17: Table 9.2.1 “Annual and unit costs for qualified nurses” – Cost per working hour (without qualification) | F17: Assumed Band 5 from Table 11.2.1 – “Nurse” | G17: Nurse | H17: 15 | I17: =(C17/60)*H17 -> 11.75
A18: 38004499 | B18: Social Worker | C18: 48 | D18: hourly | E18: Table 10.1.1 “Costs and unit estimations for a social worker (adult services)” – Cost per working hour (without qualification) | F18: Assumed match to Social worker (adult services) | G18: Social | H18: 5 | I18: =(C18/60)*H18 -> 4
A19: 38003810 | B19: Pharmacist | C19: 57 | D19: hourly | E19: Table 8.2.1 “Annual and unit costs for community-based scientific & professional staff” – Cost per working hour (without qualification) | F19: Table 12.3.6 “Agenda for Change Bands for Pharmacists” – Band 6 Pharmacist | G19: AHP | H19: 15 | I19: =(C19/60)*H19 -> 14.25
A20: 38003659 | B20: Marriage and Family Therapist | C20: 57 | D20: hourly | E20: Table 8.2.1 “Annual and unit costs for community-based scientific & professional staff” – Cost per working hour (without qualification) | F20: Table 8.1 “Agenda for Change bands for scientific & professional staff” – assumed Band 6 Therapist | G20: AHP | H20: 20 | I20: =(C20/60)*H20 -> 19
A21: 38004390 | B21: Clinical Nurse Specialist | C21: 58 | D21: hourly | E21: Table 9.2.1 “Annual and unit costs for qualified nurses” – Cost per working hour (without qualification) | F21: Band 6 from Table 11.2.1 “Agenda for Change (AfC) bands for hospital-based nurses” – mapped title | G21: Nurse | H21: 30 | I21: =(C21/60)*H21 -> 29
A22: 38004487 | B22: Nurse Practitioner | C22: 58 | D22: hourly | E22: Table 9.2.1 “Annual and unit costs for qualified nurses” – Cost per working hour (without qualification) | F22: Band 6 from Table 11.2.1 “Agenda for Change (AfC) bands for hospital-based nurses” – mapped title | G22: Nurse | H22: 30 | I22: =(C22/60)*H22 -> 29
A23: 38004413 | B23: Community Psych / Mental Health Nurse | C23: 58 | D23: hourly | E23: Table 9.2.1 “Annual and unit costs for qualified nurses” – Cost per working hour (without qualification) | F23: Band 6 from Table 11.2.1 “Agenda for Change (AfC) bands for hospital-based nurses” – mapped title | G23: Nurse | H23: 20 | I23: =(C23/60)*H23 -> 19.333333
A24: 38003807 | B24: Midwife | C24: 58 | D24: hourly | E24: Table 9.2.1 “Annual and unit costs for qualified nurses” – Cost per working hour (without qualification) | F24: Band 6 from Table 11.2.1 – mapped title | G24: Nurse | H24: 20 | I24: =(C24/60)*H24 -> 19.333333
A25: 38003638 | B25: Behavioral Health & Social Service Providers, Psychologist, Clinical | C25: 68 | D25: hourly | E25: Table 8.2.1 “Annual and unit costs for community-based scientific & professional staff” – Cost per working hour (without qualification) | F25: Table 12.3.5 “Agenda for Change Bands for Psychologists” – Band 7 Clinical Psychologist | G25: Non-registered other | H25: 20 | I25: =(C25/60)*H25 -> 22.666667
A26: 38003648 | B26: Mental Retardation and Developmental Disability Psychologist | C26: 68 | D26: hourly | E26: Table 8.2.1 “Annual and unit costs for community-based scientific & professional staff” – Cost per working hour (without qualification) | F26: Table 12.3.5 “Agenda for Change Bands for Psychologists” – Band 7 Clinical Psychologist | G26: Non-registered other | H26: 20 | I26: =(C26/60)*H26 -> 22.666667
A27: 38004370 | B27: Medical Physician Assistant | C27: 22984 | D27: annual | E27: Table 12.2.1 “Mean annual basic pay per FTE for non‑medical occupational groupings” – Healthcare assistants and other support staff | G27: Non-registered other | H27: 20 | I27: =(C27/((52*37.5)-217.5-60)/60)*H27 -> 4.5807673
A28: 38004512 | B28: Physician Assistant | C28: 22984 | D28: annual | E28: Table 12.2.1 “Mean annual basic pay per FTE for non‑medical occupational groupings” – Healthcare assistants and other support staff | G28: Non-registered other | H28: 20 | I28: =(C28/((52*37.5)-217.5-60)/60)*H28 -> 4.5807673
A29: 38004145 | B29: Phlebotomist | C29: 22984 | D29: annual | E29: Table 12.2.1 “Mean annual basic pay per FTE for non‑medical occupational groupings” – Healthcare assistants and other support staff | G29: Non-registered other | H29: 10 | I29: =(C29/((52*37.5)-217.5-60)/60)*H29 -> 2.2903837
A30: 38004371 | B30: Surgical Physician Assistant | C30: 22984 | D30: annual | E30: Table 12.2.1 “Mean annual basic pay per FTE for non‑medical occupational groupings” – Healthcare assistants and other support staff | G30: Non-registered other | H30: 10 | I30: =(C30/((52*37.5)-217.5-60)/60)*H30 -> 2.2903837
A31: 38004445 | B31: Student | C31: 27214 | D31: annual | E31: Table 12.2.1 “Mean annual basic pay per FTE for non‑medical occupational groupings” – Nursing, midwifery and health visiting learners | G31: Non-registered other | H31: 20 | I31: =(C31/((52*37.5)-217.5-60)/60)*H31 -> 5.4238166
A32: 38004185 | B32: Other Technician | C32: 30238 | D32: annual | E32: Table 12.2.5 “Mean annual basic pay per FTE for NHS staff groups” – Admin & Clerical | G32: Admin | H32: 5 | I32: =(C32/((52*37.5)-217.5-60)/60)*H32 -> 1.5066268
A33: 38004154 | B33: Registered Record Administrator | C33: 30238 | D33: annual | E33: Table 12.2.5 “Mean annual basic pay per FTE for NHS staff groups” – Admin & Clerical | G33: Admin | H33: 10 | I33: =(C33/((52*37.5)-217.5-60)/60)*H33 -> 3.0132536
A34: 38004169 | B34: Health Information Technician | C34: 30238 | D34: annual | E34: Table 12.2.5 “Mean annual basic pay per FTE for NHS staff groups” – Admin & Clerical | G34: Admin | H34: 5 | I34: =(C34/((52*37.5)-217.5-60)/60)*H34 -> 1.5066268
A35: 38003819 | B35: Pharmacy Technician | C35: 30238 | D35: annual | E35: Table 12.2.5 “Mean annual basic pay per FTE for NHS staff groups” – Admin & Clerical | G35: Non-registered other | H35: 20 | I35: =(C35/((52*37.5)-217.5-60)/60)*H35 -> 6.0265072
A36: 38004153 | B36: Physician Office Based Coding Specialist | C36: 30238 | D36: annual | E36: Table 12.2.5 “Mean annual basic pay per FTE for NHS staff groups” – Admin & Clerical | G36: Admin | H36: 1 | I36: =(C36/((52*37.5)-217.5-60)/60)*H36 -> 0.30132536
A37: 38003781 | B37: Case Manager / Care Coordinator | C37: 62428 | D37: annual | E37: Table 12.2.5 “Mean annual basic pay per FTE for NHS staff groups” – Managers | G37: Admin | H37: 10 | I37: =(C37/((52*37.5)-217.5-60)/60)*H37 -> 6.2210264
A38: 38003789 | B38: Community Health Worker | C38: 62428 | D38: annual | E38: Table 12.2.5 “Mean annual basic pay per FTE for NHS staff groups” – Managers | G38: Service | H38: 5 | I38: =(C38/((52*37.5)-217.5-60)/60)*H38 -> 3.1105132

Sheet omop_source
A1: specialty_source_value | B1: PSSRU cost | C1: Unit type | D1: Source in PSSRU | E1: Band (source/assumption) | F1: category | G1: Expected mean duration | H1: unit_cost_encounter | I1: Notes
A2: Advanced Practitioner | B2: 58 | C2: hourly | D2: Table 9.2.1 “Annual and unit costs for qualified nurses” – Cost per working hour (without qualification) | E2: Band 6 from Table 11.2.1 “Agenda for Change (AfC) bands for hospital-based nurses” – mapped title | F2: Nurse | G2: 20 | H2: 19.333333 | I2: GF assigned category
A3: Analyst | B3: 30238 | C3: annual | D3: Table 12.2.5 “Mean annual basic pay per FTE for NHS staff groups” – Admin & Clerical | F3: Admin | G3: 5 | H3: 1.5066268 | I3: based on 52 weeks, 37.5hrs pw, annual leave (217.5, based on 29 days which corresponds to NHS employees with 5 to 10 years of service) and bank holidays (8 days) / GF assigned duration
A4: Appointments Clerk | B4: 30238 | C4: annual | D4: Table 12.2.5 “Mean annual basic pay per FTE for NHS staff groups” – Admin & Clerical | F4: Admin | G4: 1 | H4: 0.30132536 | I4: based on 52 weeks, 37.5hrs pw, annual leave (217.5, based on 29 days which corresponds to NHS employees with 5 to 10 years of service) and bank holidays (8 days)
A5: Art Therapist | B5: 68 | C5: hourly | D5: Table 8.2.1 “Annual and unit costs for community-based scientific & professional staff” – Cost per working hour (without qualification) | E5: Table 8.1 “Agenda for Change bands for scientific & professional staff” – assumed Band 7 Arts Therapist | F5: AHP | G5: 20 | H5: 22.666667
A6: Art Therapist Consultant | B6: 106 | C6: hourly | D6: Table 8.2.1 “Annual and unit costs for community-based scientific & professional staff” – Cost per working hour (without qualification) | E6: Table 8.1 “Agenda for Change bands for scientific & professional staff” – assumed Band 8c Arts therapies consultant | F6: AHP | G6: 15 | H6: 26.5
A7: Art Therapist Manager | B7: 106 | C7: hourly | D7: Table 8.2.1 “Annual and unit costs for community-based scientific & professional staff” – Cost per working hour (without qualification) | E7: Table 8.1 “Agenda for Change bands for scientific & professional staff” – assumed Band 8c Head of arts therapies | F7: AHP | G7: 20 | H7: 35.333333
A8: Art Therapist Specialist Practitioner | B8: 77 | C8: hourly | D8: Table 8.2.1 “Annual and unit costs for community-based scientific & professional staff” – Cost per working hour (without qualification) | E8: Table 8.1 “Agenda for Change bands for scientific & professional staff” – assumed Band 8a Arts Therapist principal | F8: AHP | G8: 15 | H8: 19.25
A9: Assistant GP | B9: 39 | C9: hourly | D9: Table 8.2.1 “Annual and unit costs for community-based scientific & professional staff” – Cost per working hour (without qualification) | E9: Table 8.1 “Agenda for Change bands for scientific & professional staff” – assumed Band 4 Assistant practitioner | F9: Non-registered other | G9: 15 | H9: 9.75
A10: Assistant Practitioner | B10: 39 | C10: hourly | D10: Table 8.2.1 “Annual and unit costs for community-based scientific & professional staff” – Cost per working hour (without qualification) | E10: Table 8.1 “Agenda for Change bands for scientific & professional staff” – assumed Band 4 Assistant Practitioner | F10: Non-registered other | G10: 20 | H10: 13
A11: Assistant Psychologist | B11: 39 | C11: hourly | D11: Table 8.2.1 “Annual and unit costs for community-based scientific & professional staff” – Cost per working hour (without qualification) | E11: Table 12.3.5 “Agenda for Change Bands for Psychologists” – Band 4 Clinical psychology assistant practitioner | F11: Non-registered other | G11: 20 | H11: =(B11/60)*G11 -> 13 | I11: GF assigned category and duration
A12: Associate Practitioner | B12: 39 | C12: hourly | D12: Table 9.2.1 “Annual and unit costs for qualified nurses” – Cost per working hour (without qualification) | E12: Band 4 from Table 11.2.1 – mapped title | F12: Non-registered other | G12: 20 | H12: 13
A13: Associate Practitioner - General Practitioner | B13: 3.7 | C13: per minute | D13: Table 9.4.2 “Unit costs for a GP” – Cost per minute of patient contact (without qualification) | F13: GP | G13: 15 | H13: 55.5
A14: Associate Practitioner - Nurse | B14: 47 | C14: hourly | D14: Table 9.2.1 “Annual and unit costs for qualified nurses” – Cost per working hour (without qualification) | E14: Assumed Band 5 from Table 11.2.1 – “Nurse” | F14: Nurse | G14: 15 | H14: 11.75
A15: Associate Specialist | B15: 3.7 | C15: per minute | D15: Table 9.4.2 “Unit costs for a GP” – Cost per minute of patient contact (without qualification) | F15: Non-registered other | G15: 20 | H15: 74
A16: Asst. Clinical Medical Officer | B16: 3.7 | C16: per minute | D16: Table 9.4.2 “Unit costs for a GP” – Cost per minute of patient contact (without qualification) | F16: Medic non-GP | G16: 15 | H16: 55.5 | I16: GF assigned category
A17: Audiologist | B17: 44 | C17: hourly | D17: Table 8.2.1 “Annual and unit costs for community-based scientific & professional staff” – Cost per working hour (without qualification) | E17: Table 8.1 “Agenda for Change bands for scientific & professional staff” – assumed Band 5 Audiologist | F17: AHP | G17: 20 | H17: 14.666667
A18: Audit Manager | B18: 62428 | C18: annual | D18: Table 12.2.5 “Mean annual basic pay per FTE for NHS staff groups” – Managers | F18: Admin | G18: 1 | H18: 0.62210264 | I18: based on 52 weeks, 37.5hrs pw, annual leave (217.5, based on 29 days which corresponds to NHS employees with 5 to 10 years of service) and bank holidays (8 days)
A19: Availability Monitor | B19: 30238 | C19: annual | D19: Table 12.2.5 “Mean annual basic pay per FTE for NHS staff groups” – Admin & Clerical | F19: Admin | G19: 1 | H19: 0.30132536 | I19: based on 52 weeks, 37.5hrs pw, annual leave (217.5, based on 29 days which corresponds to NHS employees with 5 to 10 years of service) and bank holidays (8 days)
A20: Biomedical Scientist | B20: 44 | C20: hourly | D20: Table 8.2.1 “Annual and unit costs for community-based scientific & professional staff” – Cost per working hour (without qualification) | E20: Table 8.1 “Agenda for Change bands for scientific & professional staff” – assumed Band 5 Biomedical Scientist | F20: AHP | G20: 20 | H20: 14.666667
A21: Caldicott Guardian | B21: 90859 | C21: annual | D21: Table 12.2.5 “Mean annual basic pay per FTE for NHS staff groups” – Senior managers | F21: Medic non-GP | G21: 5 | H21: 4.5271051 | I21: based on 52 weeks, 37.5hrs pw, annual leave (217.5, based on 29 days which corresponds to NHS employees with 5 to 10 years of service) and bank holidays (8 days) / GF assigned category and duration
A22: Call Operator | B22: 30238 | C22: annual | D22: Table 12.2.5 “Mean annual basic pay per FTE for NHS staff groups” – Admin & Clerical | F22: Admin | G22: 2 | H22: 0.60265072 | I22: based on 52 weeks, 37.5hrs pw, annual leave (217.5, based on 29 days which corresponds to NHS employees with 5 to 10 years of service) and bank holidays (8 days)
A23: Chaplain | B23: 22984 | C23: annual | D23: Table 12.2.1 “Mean annual basic pay per FTE for non‑medical occupational groupings” – Healthcare assistants and other support staff | F23: Non-registered other | G23: 10 | H23: 2.2903837
A24: Child Protection worker | B24: 48 | C24: hourly | D24: Table 10.1.1 “Costs and unit estimations for a social worker (adult services)” – Cost per working hour (without qualification) | E24: Assumed match to Social worker (adult services) | F24: Social | G24: 5 | H24: 4 | I24: GF assigned duration
A25: Chiropodist/Podiatrist | B25: 44 | C25: hourly | D25: Table 8.2.1 “Annual and unit costs for community-based scientific & professional staff” – Cost per working hour (without qualification) | E25: Table 12.3.4 “Agenda for Change Bands for Chiropodists/Podiatrists” – Band 5 Podiatrist | F25: AHP | G25: 20 | H25: 14.666667
A26: Chiropodist/Podiatrist Consultant | B26: 106 | C26: hourly | D26: Table 8.2.1 “Annual and unit costs for community-based scientific & professional staff” – Cost per working hour (without qualification) | E26: Table 12.3.4 “Agenda for Change Bands for Chiropodists/Podiatrists” – Band 8c Podiatric consultant | F26: AHP | G26: 15 | H26: 26.5
A27: Chiropodist/Podiatrist Manager | B27: 77 | C27: hourly | D27: Table 8.2.1 “Annual and unit costs for community-based scientific & professional staff” – Cost per working hour (without qualification) | E27: Table 12.3.4 “Agenda for Change Bands for Chiropodists/Podiatrists” – Band 8a Podiatrist principal | F27: AHP | G27: 15 | H27: 19.25
A28: Chiropodist/Podiatrist Specialist Practitioner | B28: 57 | C28: hourly | D28: Table 8.2.1 “Annual and unit costs for community-based scientific & professional staff” – Cost per working hour (without qualification) | E28: Table 12.3.4 “Agenda for Change Bands for Chiropodists/Podiatrists” – Band 6 Podiatrist specialist | F28: AHP | G28: 15 | H28: 14.25
A29: Clerical Worker | B29: 30238 | C29: annual | D29: Table 12.2.5 “Mean annual basic pay per FTE for NHS staff groups” – Admin & Clerical | F29: Admin | G29: 10 | H29: 3.0132536 | I29: based on 52 weeks, 37.5hrs pw, annual leave (217.5, based on 29 days which corresponds to NHS employees with 5 to 10 years of service) and bank holidays (8 days)
A30: Clinical Application Administrator | B30: 30238 | C30: annual | D30: Table 12.2.5 “Mean annual basic pay per FTE for NHS staff groups” – Admin & Clerical | F30: Admin | G30: 1 | H30: 0.30132536 | I30: based on 52 weeks, 37.5hrs pw, annual leave (217.5, based on 29 days which corresponds to NHS employees with 5 to 10 years of service) and bank holidays (8 days)
A31: Clinical Assistant | B31: 22984 | C31: annual | D31: Table 12.2.1 “Mean annual basic pay per FTE for non‑medical occupational groupings” – Healthcare assistants and other support staff | F31: Non-registered other | G31: 10 | H31: 2.2903837 | I31: based on 52 weeks, 37.5hrs pw, annual leave (217.5, based on 29 days which corresponds to NHS employees with 5 to 10 years of service) and bank holidays (8 days)
A32: Clinical Coder | B32: 30238 | C32: annual | D32: Table 12.2.5 “Mean annual basic pay per FTE for NHS staff groups” – Admin & Clerical | F32: Admin | G32: 1 | H32: 0.30132536 | I32: based on 52 weeks, 37.5hrs pw, annual leave (217.5, based on 29 days which corresponds to NHS employees with 5 to 10 years of service) and bank holidays (8 days)
A33: Clinical Director | B33: 62428 | C33: annual | D33: Table 12.2.5 “Mean annual basic pay per FTE for NHS staff groups” – Managers | F33: Medic non-GP | G33: 5 | H33: 3.1105132 | I33: based on 52 weeks, 37.5hrs pw, annual leave (217.5, based on 29 days which corresponds to NHS employees with 5 to 10 years of service) and bank holidays (8 days) / GF assigned category
A34: Clinical Director - Medical | B34: 3.7 | C34: per minute | D34: Table 9.4.2 “Unit costs for a GP” – Cost per minute of patient contact (without qualification) | F34: Medic non-GP | G34: 15 | H34: 55.5
A35: Clinical Medical Officer | B35: 3.7 | C35: per minute | D35: Table 9.4.2 “Unit costs for a GP” – Cost per minute of patient contact (without qualification) | F35: Medic non-GP | G35: 15 | H35: 55.5
A36: Clinical Psychologist | B36: 68 | C36: hourly | D36: Table 8.2.1 “Annual and unit costs for community-based scientific & professional staff” – Cost per working hour (without qualification) | E36: Table 12.3.5 “Agenda for Change Bands for Psychologists” – Band 7 Clinical Psychologist | F36: Non-registered other | G36: 20 | H36: 22.666667
A37: Clinical Team Manager | B37: 62428 | C37: annual | D37: Table 12.2.5 “Mean annual basic pay per FTE for NHS staff groups” – Managers | F37: Admin | G37: 15 | H37: 9.3315396 | I37: based on 52 weeks, 37.5hrs pw, annual leave (217.5, based on 29 days which corresponds to NHS employees with 5 to 10 years of service) and bank holidays (8 days)
A38: Community Administrator | B38: 30238 | C38: annual | D38: Table 12.2.5 “Mean annual basic pay per FTE for NHS staff groups” – Admin & Clerical | F38: Admin | G38: 10 | H38: 3.0132536 | I38: based on 52 weeks, 37.5hrs pw, annual leave (217.5, based on 29 days which corresponds to NHS employees with 5 to 10 years of service) and bank holidays (8 days)
A39: Community Learning Disabilities Nurse | B39: 58 | C39: hourly | D39: Table 9.2.1 “Annual and unit costs for qualified nurses” – Cost per working hour (without qualification) | E39: Band 6 from Table 11.2.1 “Agenda for Change (AfC) bands for hospital-based nurses” – mapped title | F39: Nurse | G39: 20 | H39: 19.333333
A40: Community Mental Health Nurse | B40: 58 | C40: hourly | D40: Table 9.2.1 “Annual and unit costs for qualified nurses” – Cost per working hour (without qualification) | E40: Band 6 from Table 11.2.1 “Agenda for Change (AfC) bands for hospital-based nurses” – mapped title | F40: Nurse | G40: 20 | H40: 19.333333
...

Sheet master_omop_stand_source
A1: specialty_source_value | B1: unit_cost_omop_source | C1: category_omop_source | D1: specialty_concept_id | E1: concept_name | F1: unit_cost_omop_standard | G1: category_omop_standard | H1: DIFFERENCE OMOP_SOURCE-STANDARD
A2: Senior Manager | B2: =VLOOKUP(A2,omop_source!$A$2:$H$179,8,FALSE) -> 9.0542103 | C2: =VLOOKUP(A2,omop_source!$A$2:$H$179,6,FALSE) -> Admin | D2: 38003781 | E2: Case Manager / Care Coordinator | F2: =VLOOKUP(D2,omop_standard!$A$2:$I$38,9,FALSE) -> 6.2210264 | G2: =VLOOKUP(D2,omop_standard!$A$2:$I$38,7,FALSE) -> Admin | H2: =B2-F2 -> 2.8331839
A3: Manager | B3: =VLOOKUP(A3,omop_source!$A$2:$H$179,8,FALSE) -> 6.2210264 | C3: =VLOOKUP(A3,omop_source!$A$2:$H$179,6,FALSE) -> Admin | D3: 38003781 | E3: Case Manager / Care Coordinator | F3: =VLOOKUP(D3,omop_standard!$A$2:$I$38,9,FALSE) -> 6.2210264 | G3: =VLOOKUP(D3,omop_standard!$A$2:$I$38,7,FALSE) -> Admin | H3: =B3-F3 -> 0
A4: Community Administrator | B4: =VLOOKUP(A4,omop_source!$A$2:$H$179,8,FALSE) -> 3.0132536 | C4: =VLOOKUP(A4,omop_source!$A$2:$H$179,6,FALSE) -> Admin | D4: 38003789 | E4: Community Health Worker | F4: =VLOOKUP(D4,omop_standard!$A$2:$I$38,9,FALSE) -> 3.1105132 | G4: =VLOOKUP(D4,omop_standard!$A$2:$I$38,7,FALSE) -> Service | H4: =B4-F4 -> -0.097259591
A5: Analyst | B5: =VLOOKUP(A5,omop_source!$A$2:$H$179,8,FALSE) -> 1.5066268 | C5: =VLOOKUP(A5,omop_source!$A$2:$H$179,6,FALSE) -> Admin | D5: 38004169 | E5: Health Information Technician | F5: =VLOOKUP(D5,omop_standard!$A$2:$I$38,9,FALSE) -> 1.5066268 | G5: =VLOOKUP(D5,omop_standard!$A$2:$I$38,7,FALSE) -> Admin | H5: =B5-F5 -> 0
A6: Desktop Support Administrator | B6: =VLOOKUP(A6,omop_source!$A$2:$H$179,8,FALSE) -> 0.30132536 | C6: =VLOOKUP(A6,omop_source!$A$2:$H$179,6,FALSE) -> Admin | D6: 38004169 | E6: Health Information Technician | F6: =VLOOKUP(D6,omop_standard!$A$2:$I$38,9,FALSE) -> 1.5066268 | G6: =VLOOKUP(D6,omop_standard!$A$2:$I$38,7,FALSE) -> Admin | H6: =B6-F6 -> -1.2053014
A7: Support, Time, Recovery Worker | B7: =VLOOKUP(A7,omop_source!$A$2:$H$179,8,FALSE) -> 0.35506726 | C7: =VLOOKUP(A7,omop_source!$A$2:$H$179,6,FALSE) -> Admin | D7: 38003648 | E7: Mental Retardation and Developmental Disability Psychologist | F7: =VLOOKUP(D7,omop_standard!$A$2:$I$38,9,FALSE) -> 22.666667 | G7: =VLOOKUP(D7,omop_standard!$A$2:$I$38,7,FALSE) -> Non-registered other | H7: =B7-F7 -> -22.311599
A8: Senior Administrator | B8: =VLOOKUP(A8,omop_source!$A$2:$H$179,8,FALSE) -> 9.0542103 | C8: =VLOOKUP(A8,omop_source!$A$2:$H$179,6,FALSE) -> Admin | D8: 38004185 | E8: Other Technician | F8: =VLOOKUP(D8,omop_standard!$A$2:$I$38,9,FALSE) -> 1.5066268 | G8: =VLOOKUP(D8,omop_standard!$A$2:$I$38,7,FALSE) -> Admin | H8: =B8-F8 -> 7.5475835
A9: Desktop Support Technician | B9: =VLOOKUP(A9,omop_source!$A$2:$H$179,8,FALSE) -> 0.30132536 | C9: =VLOOKUP(A9,omop_source!$A$2:$H$179,6,FALSE) -> Admin | D9: 38004185 | E9: Other Technician | F9: =VLOOKUP(D9,omop_standard!$A$2:$I$38,9,FALSE) -> 1.5066268 | G9: =VLOOKUP(D9,omop_standard!$A$2:$I$38,7,FALSE) -> Admin | H9: =B9-F9 -> -1.2053014
A10: Secretary | B10: =VLOOKUP(A10,omop_source!$A$2:$H$179,8,FALSE) -> 3.0132536 | C10: =VLOOKUP(A10,omop_source!$A$2:$H$179,6,FALSE) -> Admin | D10: 38004185 | E10: Other Technician | F10: =VLOOKUP(D10,omop_standard!$A$2:$I$38,9,FALSE) -> 1.5066268 | G10: =VLOOKUP(D10,omop_standard!$A$2:$I$38,7,FALSE) -> Admin | H10: =B10-F10 -> 1.5066268
A11: Receptionist | B11: =VLOOKUP(A11,omop_source!$A$2:$H$179,8,FALSE) -> 0.60265072 | C11: =VLOOKUP(A11,omop_source!$A$2:$H$179,6,FALSE) -> Admin | D11: 38004185 | E11: Other Technician | F11: =VLOOKUP(D11,omop_standard!$A$2:$I$38,9,FALSE) -> 1.5066268 | G11: =VLOOKUP(D11,omop_standard!$A$2:$I$38,7,FALSE) -> Admin | H11: =B11-F11 -> -0.90397608
A12: Helpdesk Administrator | B12: =VLOOKUP(A12,omop_source!$A$2:$H$179,8,FALSE) -> 0.30132536 | C12: =VLOOKUP(A12,omop_source!$A$2:$H$179,6,FALSE) -> Admin | D12: 38004185 | E12: Other Technician | F12: =VLOOKUP(D12,omop_standard!$A$2:$I$38,9,FALSE) -> 1.5066268 | G12: =VLOOKUP(D12,omop_standard!$A$2:$I$38,7,FALSE) -> Admin | H12: =B12-F12 -> -1.2053014
A13: Clinical Coder | B13: =VLOOKUP(A13,omop_source!$A$2:$H$179,8,FALSE) -> 0.30132536 | C13: =VLOOKUP(A13,omop_source!$A$2:$H$179,6,FALSE) -> Admin | D13: 38004153 | E13: Physician Office Based Coding Specialist | F13: =VLOOKUP(D13,omop_standard!$A$2:$I$38,9,FALSE) -> 0.30132536 | G13: =VLOOKUP(D13,omop_standard!$A$2:$I$38,7,FALSE) -> Admin | H13: =B13-F13 -> 0
... A18: System Administrator | B18: =VLOOKUP(A18,omop_source!$A$2:$H$179,8,FALSE) -> 0.30132536 | C18: =VLOOKUP(A18,omop_source!$A$2:$H$179,6,FALSE) -> Admin | D18: 38004154 | E18: Registered Record Administrator | F18: =VLOOKUP(D18,omop_standard!$A$2:$I$38,9,FALSE) -> 3.0132536 | G18: =VLOOKUP(D18,omop_standard!$A$2:$I$38,7,FALSE) -> Admin | H18: =B18-F18 -> -2.7119283
A19: Mental Health Act Administrator | B19: =VLOOKUP(A19,omop_source!$A$2:$H$179,8,FALSE) -> 0.30132536 | C19: =VLOOKUP(A19,omop_source!$A$2:$H$179,6,FALSE) -> Admin | F19: =VLOOKUP(D19,omop_standard!$A$2:$I$38,9,FALSE) -> 7.3333333 | G19: NA | H19: =B19-F19 -> -7.032008
A20: Other Community Health Service - Admin Clerk | B20: =VLOOKUP(A20,omop_source!$A$2:$H$179,8,FALSE) -> 0.30132536 | C20: =VLOOKUP(A20,omop_source!$A$2:$H$179,6,FALSE) -> Admin | F20: =VLOOKUP(D20,omop_standard!$A$2:$I$38,9,FALSE) -> 7.3333333 | G20: NA | H20: =B20-F20 -> -7.032008
A21: Clinical Team Manager | B21: =VLOOKUP(A21,omop_source!$A$2:$H$179,8,FALSE) -> 9.3315396 | C21: =VLOOKUP(A21,omop_source!$A$2:$H$179,6,FALSE) -> Admin | F21: =VLOOKUP(D21,omop_standard!$A$2:$I$38,9,FALSE) -> 7.3333333 | G21: NA | H21: =B21-F21 -> 1.9982063
A22: Call Operator | B22: =VLOOKUP(A22,omop_source!$A$2:$H$179,8,FALSE) -> 0.60265072 | C22: =VLOOKUP(A22,omop_source!$A$2:$H$179,6,FALSE) -> Admin | F22: =VLOOKUP(D22,omop_standard!$A$2:$I$38,9,FALSE) -> 7.3333333 | G22: NA | H22: =B22-F22 -> -6.7306826
A23: Ward Manager | B23: =VLOOKUP(A23,omop_source!$A$2:$H$179,8,FALSE) -> 11.5 | C23: =VLOOKUP(A23,omop_source!$A$2:$H$179,6,FALSE) -> Admin | F23: =VLOOKUP(D23,omop_standard!$A$2:$I$38,9,FALSE) -> 7.3333333 | G23: NA | H23: =B23-F23 -> 4.1666667
A24: Waiting List Clerk | B24: =VLOOKUP(A24,omop_source!$A$2:$H$179,8,FALSE) -> 0.30132536 | C24: =VLOOKUP(A24,omop_source!$A$2:$H$179,6,FALSE) -> Admin | F24: =VLOOKUP(D24,omop_standard!$A$2:$I$38,9,FALSE) -> 7.3333333 | G24: NA | H24: =B24-F24 -> -7.032008
A25: Information Officer | B25: =VLOOKUP(A25,omop_source!$A$2:$H$179,8,FALSE) -> 0.30132536 | C25: =VLOOKUP(A25,omop_source!$A$2:$H$179,6,FALSE) -> Admin | F25: =VLOOKUP(D25,omop_standard!$A$2:$I$38,9,FALSE) -> 7.3333333 | G25: NA | H25: =B25-F25 -> -7.032008
A26: Appointments Clerk | B26: =VLOOKUP(A26,omop_source!$A$2:$H$179,8,FALSE) -> 0.30132536 | C26: =VLOOKUP(A26,omop_source!$A$2:$H$179,6,FALSE) -> Admin | F26: =VLOOKUP(D26,omop_standard!$A$2:$I$38,9,FALSE) -> 7.3333333 | G26: NA | H26: =B26-F26 -> -7.032008
A27: Health Records Clerk | B27: =VLOOKUP(A27,omop_source!$A$2:$H$179,8,FALSE) -> 3.0132536 | C27: =VLOOKUP(A27,omop_source!$A$2:$H$179,6,FALSE) -> Admin | F27: =VLOOKUP(D27,omop_standard!$A$2:$I$38,9,FALSE) -> 7.3333333 | G27: NA | H27: =B27-F27 -> -4.3200797
A28: Outpatient Manager | B28: =VLOOKUP(A28,omop_source!$A$2:$H$179,8,FALSE) -> 6.2210264 | C28: =VLOOKUP(A28,omop_source!$A$2:$H$179,6,FALSE) -> Admin | F28: =VLOOKUP(D28,omop_standard!$A$2:$I$38,9,FALSE) -> 7.3333333 | G28: NA | H28: =B28-F28 -> -1.1123069
A29: Network Administrator | B29: =VLOOKUP(A29,omop_source!$A$2:$H$179,8,FALSE) -> 0.30132536 | C29: =VLOOKUP(A29,omop_source!$A$2:$H$179,6,FALSE) -> Admin | F29: =VLOOKUP(D29,omop_standard!$A$2:$I$38,9,FALSE) -> 7.3333333 | G29: NA | H29: =B29-F29 -> -7.032008
A30: Medical Records Manager | B30: =VLOOKUP(A30,omop_source!$A$2:$H$179,8,FALSE) -> 0.30132536 | C30: =VLOOKUP(A30,omop_source!$A$2:$H$179,6,FALSE) -> Admin | F30: =VLOOKUP(D30,omop_standard!$A$2:$I$38,9,FALSE) -> 7.3333333 | G30: NA | H30: =B30-F30 -> -7.032008
... A78: Regional Dental Officer | B78: =VLOOKUP(A78,omop_source!$A$2:$H$179,8,FALSE) -> 12.442053 | C78: =VLOOKUP(A78,omop_source!$A$2:$H$179,6,FALSE) -> Dental | F78: =VLOOKUP(D78,omop_standard!$A$2:$I$38,9,FALSE) -> 7.3333333 | G78: NA | H78: =B78-F78 -> 5.1087195
A79: Sessional GP | B79: =VLOOKUP(A79,omop_source!$A$2:$H$179,8,FALSE) -> 55.5 | C79: =VLOOKUP(A79,omop_source!$A$2:$H$179,6,FALSE) -> GP | D79: 0 | E79: No matching concept | F79: =VLOOKUP(D79,omop_standard!$A$2:$I$38,9,FALSE) -> 7.3333333 | G79: =VLOOKUP(D79,omop_standard!$A$2:$I$38,7,FALSE) -> Uncategorised | H79: =B79-F79 -> 48.166667
A80: GP Registrar | B80: =VLOOKUP(A80,omop_source!$A$2:$H$179,8,FALSE) -> 55.5 | C80: =VLOOKUP(A80,omop_source!$A$2:$H$179,6,FALSE) -> GP | D80: 0 | E80: No matching concept | F80: =VLOOKUP(D80,omop_standard!$A$2:$I$38,9,FALSE) -> 7.3333333 | G80: =VLOOKUP(D80,omop_standard!$A$2:$I$38,7,FALSE) -> Uncategorised | H80: =B80-F80 -> 48.166667
A81: Locum GP | B81: =VLOOKUP(A81,omop_source!$A$2:$H$179,8,FALSE) -> 55.5 | C81: =VLOOKUP(A81,omop_source!$A$2:$H$179,6,FALSE) -> GP | D81: 0 | E81: No matching concept | F81: =VLOOKUP(D81,omop_standard!$A$2:$I$38,9,FALSE) -> 7.3333333 | G81: =VLOOKUP(D81,omop_standard!$A$2:$I$38,7,FALSE) -> Uncategorised | H81: =B81-F81 -> 48.166667
A82: Psychiatrist | B82: =VLOOKUP(A82,omop_source!$A$2:$H$179,8,FALSE) -> 40.333333 | C82: =VLOOKUP(A82,omop_source!$A$2:$H$179,6,FALSE) -> Medic non-GP | F82: =VLOOKUP(D82,omop_standard!$A$2:$I$38,9,FALSE) -> 7.3333333 | G82: NA | H82: =B82-F82 -> 33
A83: Clinical Director | B83: =VLOOKUP(A83,omop_source!$A$2:$H$179,8,FALSE) -> 3.1105132 | C83: =VLOOKUP(A83,omop_source!$A$2:$H$179,6,FALSE) -> Medic non-GP | F83: =VLOOKUP(D83,omop_standard!$A$2:$I$38,9,FALSE) -> 7.3333333 | G83: NA | H83: =B83-F83 -> -4.2228201
A84: Clinical Medical Officer | B84: =VLOOKUP(A84,omop_source!$A$2:$H$179,8,FALSE) -> 55.5 | C84: =VLOOKUP(A84,omop_source!$A$2:$H$179,6,FALSE) -> Medic non-GP | F84: =VLOOKUP(D84,omop_standard!$A$2:$I$38,9,FALSE) -> 7.3333333 | G84: NA | H84: =B84-F84 -> 48.166667
A85: Hospital Practitioner | B85: =VLOOKUP(A85,omop_source!$A$2:$H$179,8,FALSE) -> 55.5 | C85: =VLOOKUP(A85,omop_source!$A$2:$H$179,6,FALSE) -> Medic non-GP | F85: =VLOOKUP(D85,omop_standard!$A$2:$I$38,9,FALSE) -> 7.3333333 | G85: NA | H85: =B85-F85 -> 48.166667
A86: Medical Director | B86: =VLOOKUP(A86,omop_source!$A$2:$H$179,8,FALSE) -> 55.5 | C86: =VLOOKUP(A86,omop_source!$A$2:$H$179,6,FALSE) -> Medic non-GP | F86: =VLOOKUP(D86,omop_standard!$A$2:$I$38,9,FALSE) -> 7.3333333 | G86: NA | H86: =B86-F86 -> 48.166667
A87: Specialist Registrar | B87: =VLOOKUP(A87,omop_source!$A$2:$H$179,8,FALSE) -> 55.5 | C87: =VLOOKUP(A87,omop_source!$A$2:$H$179,6,FALSE) -> Medic non-GP | F87: =VLOOKUP(D87,omop_standard!$A$2:$I$38,9,FALSE) -> 7.3333333 | G87: NA | H87: =B87-F87 -> 48.166667
A88: Clinical Director - Medical | B88: =VLOOKUP(A88,omop_source!$A$2:$H$179,8,FALSE) -> 55.5 | C88: =VLOOKUP(A88,omop_source!$A$2:$H$179,6,FALSE) -> Medic non-GP | F88: =VLOOKUP(D88,omop_standard!$A$2:$I$38,9,FALSE) -> 7.3333333 | G88: NA | H88: =B88-F88 -> 48.166667
A89: Practitioner | B89: =VLOOKUP(A89,omop_source!$A$2:$H$179,8,FALSE) -> 55.5 | C89: =VLOOKUP(A89,omop_source!$A$2:$H$179,6,FALSE) -> Medic non-GP | F89: =VLOOKUP(D89,omop_standard!$A$2:$I$38,9,FALSE) -> 7.3333333 | G89: NA | H89: =B89-F89 -> 48.166667
A90: Trust Grade Doctor - Career Grade level | B90: =VLOOKUP(A90,omop_source!$A$2:$H$179,8,FALSE) -> 55.5 | C90: =VLOOKUP(A90,omop_source!$A$2:$H$179,6,FALSE) -> Medic non-GP | F90: =VLOOKUP(D90,omop_standard!$A$2:$I$38,9,FALSE) -> 7.3333333 | G90: NA | H90: =B90-F90 -> 48.166667
A91: House Officer - Pre Registration | B91: =VLOOKUP(A91,omop_source!$A$2:$H$179,8,FALSE) -> 55.5 | C91: =VLOOKUP(A91,omop_source!$A$2:$H$179,6,FALSE) -> Medic non-GP | F91: =VLOOKUP(D91,omop_standard!$A$2:$I$38,9,FALSE) -> 7.3333333 | G91: NA | H91: =B91-F91 -> 48.166667
...

Sheet notes
D2: I derived a list of specialties for each datasets for the visits in the study period
D4: Code used for extraction (Source-cprd) | O4: Code used for extraction (OMOP)
D7: validation_staff <- my_dm$`validation_staff` %>% collect() | O7: visit_data_study_period <- cdm$visit_detail %>%
D8: validation_consultation <- my_dm$`validation_consultation` %>% collect() %>% | O8: # Filter for only primary care visits
D9: # Filter such that we have the visits between the study start and study end dates | O9: dplyr::filter(visit_detail_concept_id == 581477) %>%
D10: filter(consdate >= study_start_date & consdate <= study_end_date) | O10: dplyr::left_join(cdm$provider) %>%
O11: dplyr::filter(visit_detail_start_date >= study_start_date & # include only visits in the study period
O12: visit_detail_start_date <= study_end_date) %>% compute()
D13: visit_data_study_period <- inner_join (validation_consultation, validation_staff ,
D14: by = "staffid")
O15: specialty_freq <- visit_data_study_period %>%
D16: specialty_freq <- visit_data_study_period %>% | O16: group_by(specialty_source_value, specialty_concept_id) %>%
D17: count(description) %>% | O17: summarise(n = n(), .groups = "drop") %>%
D18: mutate( | O18: mutate(percent = round(100 * n / sum(n), 1)) %>%
D19: percent = round(100 * n / sum(n), 1) | O19: left_join(
D20: ) %>% | O20: cdm$concept %>%
D21: arrange(desc(n)) | O21: select(concept_id, concept_name),
O22: by = c("specialty_concept_id" = "concept_id")
D23: library(rio)
D24: export(specialty_freq, "specialty_frequency_whole_cprd_source_study_period.xlsx")
D27: Assumptions
D28: Costing was performed using the specialty categories from the source CPRD data, with unit values listed in the source_cprd sheet.
D29: OMOP specialty_concept_ids were assigned costs based on their corresponding CPRD specialties.
D30: When multiple CPRD specialties mapped to the same concept ID, an average cost was used.
D31: For source specialties that could not be mapped to a concept ID (i.e., unmatched), an average of all CPRD specialty costs was applied.
D32: In the master sheet there are values for source and omop side to side
D34: Update:
D35: Cost in omop was done blidnly from CPRD and separately using source and concept id spelcialties
