Workbook

Sheet source_cprd_aurum
A1: description | B1: PSSRU cost | C1: Unit type | D1: Source in PSSRU | E1: Band (source/assumption) | F1: category | G1: Expected mean duration consultation by Lindsey | H1: unit_cost_encounter | I1: Notes
A2: Asst. Clinical Medical Officer | B2: 3.7 | C2: per minute | D2: Table 9.4.2 “Unit costs for a GP” – Cost per minute of patient contact (without qualification) | F2: Medic non-GP | G2: 15 | H2: =G2*B2 -> 55.5 | I2: GF assigned category
A3: Hospital Practitioner | B3: 3.7 | C3: per minute | D3: Table 9.4.2 “Unit costs for a GP” – Cost per minute of patient contact (without qualification) | F3: Medic non-GP | G3: 15 | H3: =G3*B3 -> 55.5 | I3: GF assigned category
A4: Practitioner | B4: 3.7 | C4: per minute | D4: Table 9.4.2 “Unit costs for a GP” – Cost per minute of patient contact (without qualification) | F4: Medic non-GP | G4: 15 | H4: =G4*B4 -> 55.5 | I4: GF assigned category
A5: System Worker | B5: 39 | C5: hourly | D5: Table 8.2.1 “Annual and unit costs for community-based scientific & professional staff” – Cost per working hour (without qualification) | E5: Table 8.1 “Agenda for Change bands for scientific & professional staff” – assumed Band 4 System Worker | F5: Non-registered other | G5: 5 | H5: =(B5/60)*G5 -> 3.25 | I5: GF assigned category and duration
A6: Multi Therapist Specialist Practitioner | B6: 77 | C6: hourly | D6: Table 8.2.1 “Annual and unit costs for community-based scientific & professional staff” – Cost per working hour (without qualification) | E6: Table 8.1 “Agenda for Change bands for scientific & professional staff” – assumed Band 8a Therapy principal (multi) | F6: AHP | G6: 15 | H6: =(B6/60)*G6 -> 19.25 | I6: GF assigned category
A7: Officer | B7: 30238 | C7: annual | D7: Table 12.2.5 “Mean annual basic pay per FTE for NHS staff groups” – Admin & Clerical | F7: Non-registered other | G7: 5 | H7: =(B7/((52*37.5)-217.5-60)/60)*G7 -> 1.5066268 | I7: based on 52 weeks, 37.5hrs pw, annual leave (217.5, based on 29 days which corresponds to NHS employees with 5 to 10 years of service) and bank holidays (8 days) / GF assigned category and duration
A8: Patient Welfare Officer | B8: 30238 | C8: annual | D8: Table 12.2.5 “Mean annual basic pay per FTE for NHS staff groups” – Admin & Clerical | F8: Non-registered other | G8: 15 | H8: =(B8/((52*37.5)-217.5-60)/60)*G8 -> 4.5198804 | I8: based on 52 weeks, 37.5hrs pw, annual leave (217.5, based on 29 days which corresponds to NHS employees with 5 to 10 years of service) and bank holidays (8 days) / GF assigned category and duration
A9: Caldicott Guardian | B9: 90859 | C9: annual | D9: Table 12.2.5 “Mean annual basic pay per FTE for NHS staff groups” – Senior managers | F9: Medic non-GP | G9: 5 | H9: =(B9/((52*37.5)-217.5-60)/60)*G9 -> 4.5271051 | I9: based on 52 weeks, 37.5hrs pw, annual leave (217.5, based on 29 days which corresponds to NHS employees with 5 to 10 years of service) and bank holidays (8 days) / GF assigned category and duration
A10: Ward Manager | B10: 69 | C10: hourly | D10: Table 9.2.1 “Annual and unit costs for qualified nurses” – Cost per working hour (without qualification) | E10: Band 7 from Table 11.2.1 “Agenda for Change (AfC) bands for hospital-based nurses” – mapped title | F10: Admin | G10: 10 | H10: =(B10/60)*G10 -> 11.5 | I10: GF assigned category
A11: Analyst | B11: 30238 | C11: annual | D11: Table 12.2.5 “Mean annual basic pay per FTE for NHS staff groups” – Admin & Clerical | F11: Admin | G11: 5 | H11: =(B11/((52*37.5)-217.5-60)/60)*G11 -> 1.5066268 | I11: based on 52 weeks, 37.5hrs pw, annual leave (217.5, based on 29 days which corresponds to NHS employees with 5 to 10 years of service) and bank holidays (8 days) / GF assigned duration
A12: Appointments Clerk | B12: 30238 | C12: annual | D12: Table 12.2.5 “Mean annual basic pay per FTE for NHS staff groups” – Admin & Clerical | F12: Admin | G12: 1 | H12: =(B12/((52*37.5)-217.5-60)/60)*G12 -> 0.30132536 | I12: based on 52 weeks, 37.5hrs pw, annual leave (217.5, based on 29 days which corresponds to NHS employees with 5 to 10 years of service) and bank holidays (8 days)
A13: Availability Monitor | B13: 30238 | C13: annual | D13: Table 12.2.5 “Mean annual basic pay per FTE for NHS staff groups” – Admin & Clerical | F13: Admin | G13: 1 | H13: =(B13/((52*37.5)-217.5-60)/60)*G13 -> 0.30132536 | I13: based on 52 weeks, 37.5hrs pw, annual leave (217.5, based on 29 days which corresponds to NHS employees with 5 to 10 years of service) and bank holidays (8 days)
A14: Call Operator | B14: 30238 | C14: annual | D14: Table 12.2.5 “Mean annual basic pay per FTE for NHS staff groups” – Admin & Clerical | F14: Admin | G14: 2 | H14: =(B14/((52*37.5)-217.5-60)/60)*G14 -> 0.60265072 | I14: based on 52 weeks, 37.5hrs pw, annual leave (217.5, based on 29 days which corresponds to NHS employees with 5 to 10 years of service) and bank holidays (8 days)
A15: Clerical Worker | B15: 30238 | C15: annual | D15: Table 12.2.5 “Mean annual basic pay per FTE for NHS staff groups” – Admin & Clerical | F15: Admin | G15: 5 | H15: =(B15/((52*37.5)-217.5-60)/60)*G15 -> 1.5066268 | I15: based on 52 weeks, 37.5hrs pw, annual leave (217.5, based on 29 days which corresponds to NHS employees with 5 to 10 years of service) and bank holidays (8 days)
A16: Clinical Application Administrator | B16: 30238 | C16: annual | D16: Table 12.2.5 “Mean annual basic pay per FTE for NHS staff groups” – Admin & Clerical | F16: Admin | G16: 1 | H16: =(B16/((52*37.5)-217.5-60)/60)*G16 -> 0.30132536 | I16: based on 52 weeks, 37.5hrs pw, annual leave (217.5, based on 29 days which corresponds to NHS employees with 5 to 10 years of service) and bank holidays (8 days)
A17: Clinical Coder | B17: 30238 | C17: annual | D17: Table 12.2.5 “Mean annual basic pay per FTE for NHS staff groups” – Admin & Clerical | F17: Admin | G17: 1 | H17: =(B17/((52*37.5)-217.5-60)/60)*G17 -> 0.30132536 | I17: based on 52 weeks, 37.5hrs pw, annual leave (217.5, based on 29 days which corresponds to NHS employees with 5 to 10 years of service) and bank holidays (8 days)
A18: Community Administrator | B18: 30238 | C18: annual | D18: Table 12.2.5 “Mean annual basic pay per FTE for NHS staff groups” – Admin & Clerical | F18: Admin | G18: 10 | H18: =(B18/((52*37.5)-217.5-60)/60)*G18 -> 3.0132536 | I18: based on 52 weeks, 37.5hrs pw, annual leave (217.5, based on 29 days which corresponds to NHS employees with 5 to 10 years of service) and bank holidays (8 days)
A19: Desktop Support Administrator | B19: 30238 | C19: annual | D19: Table 12.2.5 “Mean annual basic pay per FTE for NHS staff groups” – Admin & Clerical | F19: Admin | G19: 1 | H19: =(B19/((52*37.5)-217.5-60)/60)*G19 -> 0.30132536 | I19: based on 52 weeks, 37.5hrs pw, annual leave (217.5, based on 29 days which corresponds to NHS employees with 5 to 10 years of service) and bank holidays (8 days)
A20: Desktop Support Technician | B20: 30238 | C20: annual | D20: Table 12.2.5 “Mean annual basic pay per FTE for NHS staff groups” – Admin & Clerical | F20: Admin | G20: 1 | H20: =(B20/((52*37.5)-217.5-60)/60)*G20 -> 0.30132536 | I20: based on 52 weeks, 37.5hrs pw, annual leave (217.5, based on 29 days which corresponds to NHS employees with 5 to 10 years of service) and bank holidays (8 days)
A21: Health Records Administrator | B21: 30238 | C21: annual | D21: Table 12.2.5 “Mean annual basic pay per FTE for NHS staff groups” – Admin & Clerical | F21: Admin | G21: 10 | H21: =(B21/((52*37.5)-217.5-60)/60)*G21 -> 3.0132536 | I21: based on 52 weeks, 37.5hrs pw, annual leave (217.5, based on 29 days which corresponds to NHS employees with 5 to 10 years of service) and bank holidays (8 days)
A22: Health Records Clerk | B22: 30238 | C22: annual | D22: Table 12.2.5 “Mean annual basic pay per FTE for NHS staff groups” – Admin & Clerical | F22: Admin | G22: 10 | H22: =(B22/((52*37.5)-217.5-60)/60)*G22 -> 3.0132536 | I22: based on 52 weeks, 37.5hrs pw, annual leave (217.5, based on 29 days which corresponds to NHS employees with 5 to 10 years of service) and bank holidays (8 days)
... A48: Senior Manager | B48: 90859 | C48: annual | D48: Table 12.2.5 “Mean annual basic pay per FTE for NHS staff groups” – Senior managers | F48: Admin | G48: 10 | H48: =(B48/((52*37.5)-217.5-60)/60)*G48 -> 9.0542103 | I48: based on 52 weeks, 37.5hrs pw, annual leave (217.5, based on 29 days which corresponds to NHS employees with 5 to 10 years of service) and bank holidays (8 days)
A49: Radiologist | B49: 3.7 | C49: per minute | D49: Table 9.4.2 “Unit costs for a GP” – Cost per minute of patient contact (without qualification) | F49: AHP | G49: 20 | H49: =G49*B49 -> 74
A50: Technician - Healthcare Scientists | B50: 39 | C50: hourly | D50: Table 8.2.1 “Annual and unit costs for community-based scientific & professional staff” – Cost per working hour (without qualification) | E50: Table 8.1 “Agenda for Change bands for scientific & professional staff” – assumed Band 4 Healthcare science technician | F50: AHP | G50: 10 | H50: =(B50/60)*G50 -> 6.5
A51: Audiologist | B51: 44 | C51: hourly | D51: Table 8.2.1 “Annual and unit costs for community-based scientific & professional staff” – Cost per working hour (without qualification) | E51: Table 8.1 “Agenda for Change bands for scientific & professional staff” – assumed Band 5 Audiologist | F51: AHP | G51: 20 | H51: =(B51/60)*G51 -> 14.666667
A52: Biomedical Scientist | B52: 44 | C52: hourly | D52: Table 8.2.1 “Annual and unit costs for community-based scientific & professional staff” – Cost per working hour (without qualification) | E52: Table 8.1 “Agenda for Change bands for scientific & professional staff” – assumed Band 5 Biomedical Scientist | F52: AHP | G52: 20 | H52: =(B52/60)*G52 -> 14.666667
A53: Chiropodist/Podiatrist | B53: 44 | C53: hourly | D53: Table 8.2.1 “Annual and unit costs for community-based scientific & professional staff” – Cost per working hour (without qualification) | E53: Table 12.3.4 “Agenda for Change Bands for Chiropodists/Podiatrists” – Band 5 Podiatrist | F53: AHP | G53: 20 | H53: =(B53/60)*G53 -> 14.666667
A54: Dietitian | B54: 44 | C54: hourly | D54: Table 8.2.1 “Annual and unit costs for community-based scientific & professional staff” – Cost per working hour (without qualification) | E54: Table 8.1 “Agenda for Change bands for scientific & professional staff” – assumed Band 5 Dietitian | F54: AHP | G54: 20 | H54: =(B54/60)*G54 -> 14.666667
A55: Occupational Therapist | B55: 44 | C55: hourly | D55: Table 8.2.1 “Annual and unit costs for community-based scientific & professional staff” – Cost per working hour (without qualification) | E55: Table 12.3.2 “Agenda for Change Bands for Occupational Therapists” – Band 5 Occupational Therapist | F55: AHP | G55: 20 | H55: =(B55/60)*G55 -> 14.666667
A56: Osteopath | B56: 44 | C56: hourly | D56: Table 8.2.1 “Annual and unit costs for community-based scientific & professional staff” – Cost per working hour (without qualification) | E56: Table 8.1 “Agenda for Change bands for scientific & professional staff” – assumed Band 5 Osteopath | F56: AHP | G56: 20 | H56: =(B56/60)*G56 -> 14.666667
A57: Paramedic | B57: 44 | C57: hourly | D57: Table 8.2.1 “Annual and unit costs for community-based scientific & professional staff” – Cost per working hour (without qualification) | E57: Table 8.1 “Agenda for Change bands for scientific & professional staff” – assumed Band 5 Paramedic (treated as AHP) | F57: AHP | G57: 20 | H57: =(B57/60)*G57 -> 14.666667
A58: Physiotherapist | B58: 44 | C58: hourly | D58: Table 8.2.1 “Annual and unit costs for community-based scientific & professional staff” – Cost per working hour (without qualification) | E58: Table 12.3.1 “Agenda for Change Bands for Physiotherapists” – Band 5 Physiotherapist | F58: AHP | G58: 20 | H58: =(B58/60)*G58 -> 14.666667
A59: Radiographer | B59: 44 | C59: hourly | D59: Table 8.2.1 “Annual and unit costs for community-based scientific & professional staff” – Cost per working hour (without qualification) | E59: Table 8.1 “Agenda for Change bands for scientific & professional staff” – assumed Band 5 Radiographer | F59: AHP | G59: 20 | H59: =(B59/60)*G59 -> 14.666667
A60: Radiographer - Diagnostic | B60: 44 | C60: hourly | D60: Table 8.2.1 “Annual and unit costs for community-based scientific & professional staff” – Cost per working hour (without qualification) | E60: Table 8.1 “Agenda for Change bands for scientific & professional staff” – assumed Band 5 Radiographer (diagnostic) | F60: AHP | G60: 20 | H60: =(B60/60)*G60 -> 14.666667
A61: Chiropodist/Podiatrist Specialist Practitioner | B61: 57 | C61: hourly | D61: Table 8.2.1 “Annual and unit costs for community-based scientific & professional staff” – Cost per working hour (without qualification) | E61: Table 12.3.4 “Agenda for Change Bands for Chiropodists/Podiatrists” – Band 6 Podiatrist specialist | F61: AHP | G61: 15 | H61: =(B61/60)*G61 -> 14.25
... A82: Paramedic Manager | B82: 106 | C82: hourly | D82: Table 8.2.1 “Annual and unit costs for community-based scientific & professional staff” – Cost per working hour (without qualification) | E82: Table 8.1 “Agenda for Change bands for scientific & professional staff” – assumed Band 8c Paramedic Manager | F82: AHP | G82: 20 | H82: =(B82/60)*G82 -> 35.333333
A83: Pre-reg Pharmacist | B83: 27214 | C83: annual | D83: Table 12.2.1 “Mean annual basic pay per FTE for non‑medical occupational groupings” – Nursing, midwifery and health visiting learners | F83: AHP | G83: 20 | H83: =(B83/((52*37.5)-217.5-60)/60)*G83 -> 5.4238166 | I83: based on 52 weeks, 37.5hrs pw, annual leave (217.5, based on 29 days which corresponds to NHS employees with 5 to 10 years of service) and bank holidays (8 days)
A84: Student Physiotherapist | B84: 27214 | C84: annual | D84: Table 12.2.1 “Mean annual basic pay per FTE for non‑medical occupational groupings” – Nursing, midwifery and health visiting learners | F84: AHP | G84: 20 | H84: =(B84/((52*37.5)-217.5-60)/60)*G84 -> 5.4238166 | I84: based on 52 weeks, 37.5hrs pw, annual leave (217.5, based on 29 days which corresponds to NHS employees with 5 to 10 years of service) and bank holidays (8 days)
A85: Regional Dental Officer | B85: 62428 | C85: annual | D85: Table 12.2.5 “Mean annual basic pay per FTE for NHS staff groups” – Managers | F85: Dental | G85: 20 | H85: =(B85/((52*37.5)-217.5-60)/60)*G85 -> 12.442053 | I85: based on 52 weeks, 37.5hrs pw, annual leave (217.5, based on 29 days which corresponds to NHS employees with 5 to 10 years of service) and bank holidays (8 days)
...

Sheet omop
A1: specialty_concept_id | B1: concept_name | C1: unit_cost_encounter | D1: category | E1: Note
A2: 38004446 | B2: General Practice | C2: =VLOOKUP(B2,master!$E$2:$F$157,2,FALSE) -> 55.5 | D2: GP | E2: Mean of corresponding source specialties
A3: 38004376 | B3: Community Health Nurse Practitioner | C3: =VLOOKUP(B3,master!$E$2:$F$157,2,FALSE) -> 74 | D3: Non-registered other | E3: same as source
A4: 38004185 | B4: Other Technician | C4: =VLOOKUP(B4,master!$E$2:$F$157,2,FALSE) -> 2.7537942 | D4: Admin | E4: Mean of corresponding source specialties
A5: 38004154 | B5: Registered Record Administrator | C5: =VLOOKUP(B5,master!$E$2:$F$157,2,FALSE) -> 1.627157 | D5: Admin | E5: Mean of corresponding source specialties
A6: 38003781 | B6: Case Manager / Care Coordinator | C6: =VLOOKUP(B6,master!$E$2:$F$157,2,FALSE) -> 7.6376183 | D6: Admin | E6: Mean of corresponding source specialties
A7: 38004370 | B7: Medical Physician Assistant | C7: =VLOOKUP(B7,master!$E$2:$F$157,2,FALSE) -> 4.5807673 | D7: Non-registered other | E7: same as source
A8: 38004512 | B8: Physician Assistant | C8: =VLOOKUP(B8,master!$E$2:$F$157,2,FALSE) -> 23.467788 | D8: Non-registered other | E8: Mean of corresponding source specialties
A9: 0 | B9: No matching concept | C9: =VLOOKUP(B9,master!$E$2:$F$157,2,FALSE) -> 18.607298 | D9: Uncategorised | E9: Mean of corresponding source specialties
A10: 38003722 | B10: Registered Community Health Nurse | C10: =VLOOKUP(B10,master!$E$2:$F$157,2,FALSE) -> 15.666667 | D10: Nurse | E10: same as source
A11: 38003789 | B11: Community Health Worker | C11: =VLOOKUP(B11,master!$E$2:$F$157,2,FALSE) -> 3.0618834 | D11: Service | E11: Mean of corresponding source specialties / category OMOP assigned by GF
A12: 38004390 | B12: Clinical Nurse Specialist | C12: =VLOOKUP(B12,master!$E$2:$F$157,2,FALSE) -> 29 | D12: Nurse | E12: same as source
A13: 38003716 | B13: Registered Nurse | C13: =VLOOKUP(B13,master!$E$2:$F$157,2,FALSE) -> 17.5 | D13: Nurse | E13: Mean of corresponding source specialties
... A37: 38003648 | B37: Mental Retardation and Developmental Disability Psychologist | C37: =VLOOKUP(B37,master!$E$2:$F$157,2,FALSE) -> 0.35506726 | D37: Admin | E37: same as source

Sheet master
A1: specialty_source_value | B1: unit_cost_source | C1: category_source | D1: concept_id_omop | E1: concept_name_omop | F1: unit_cost_omop | G1: category_omop | H1: Notes
A2: Specialist Practitioner | B2: =VLOOKUP(A2,source_cprd_aurum!$A$2:$H$158,8,FALSE) -> 14.5 | C2: =VLOOKUP(A2,source_cprd_aurum!$A$2:$F$158,6,FALSE) -> AHP | D2: 38003794 | E2: Specialist | F2: 35.944444 | G2: Non-registered other | H2: Mean of corresponding source specialties / Category OMOP assigned by GF | I2: =B2-F2 -> -21.444444
A3: Healthcare Assistant | B3: =VLOOKUP(A3,source_cprd_aurum!$A$2:$H$158,8,FALSE) -> 2.2903837 | C3: =VLOOKUP(A3,source_cprd_aurum!$A$2:$F$158,6,FALSE) -> Non-registered other | D3: 38004512 | E3: Physician Assistant | F3: 23.467788 | G3: Non-registered other | H3: Mean of corresponding source specialties | I3: =B3-F3 -> -21.177404
A4: Physician Assistant | B4: =VLOOKUP(A4,source_cprd_aurum!$A$2:$H$158,8,FALSE) -> 4.5807673 | C4: =VLOOKUP(A4,source_cprd_aurum!$A$2:$F$158,6,FALSE) -> Non-registered other | D4: 38004512 | E4: Physician Assistant | F4: 23.467788 | G4: Non-registered other | H4: Mean of corresponding source specialties | I4: =B4-F4 -> -18.88702
A5: Appointments Clerk | B5: =VLOOKUP(A5,source_cprd_aurum!$A$2:$H$158,8,FALSE) -> 0.30132536 | C5: =VLOOKUP(A5,source_cprd_aurum!$A$2:$F$158,6,FALSE) -> Admin | D5: 0 | E5: No matching concept | F5: 18.607298 | G5: Uncategorised | H5: Mean of corresponding source specialties | I5: =B5-F5 -> -18.305973
A6: Clinical Application Administrator | B6: =VLOOKUP(A6,source_cprd_aurum!$A$2:$H$158,8,FALSE) -> 0.30132536 | C6: =VLOOKUP(A6,source_cprd_aurum!$A$2:$F$158,6,FALSE) -> Admin | D6: 0 | E6: No matching concept | F6: 18.607298 | G6: Uncategorised | H6: Mean of corresponding source specialties | I6: =B6-F6 -> -18.305973
A7: Network Administrator | B7: =VLOOKUP(A7,source_cprd_aurum!$A$2:$H$158,8,FALSE) -> 0.30132536 | C7: =VLOOKUP(A7,source_cprd_aurum!$A$2:$F$158,6,FALSE) -> Admin | D7: 0 | E7: No matching concept | F7: 18.607298 | G7: Uncategorised | H7: Mean of corresponding source specialties | I7: =B7-F7 -> -18.305973
A8: Technician - Admin & Clerical | B8: =VLOOKUP(A8,source_cprd_aurum!$A$2:$H$158,8,FALSE) -> 0.30132536 | C8: =VLOOKUP(A8,source_cprd_aurum!$A$2:$F$158,6,FALSE) -> Admin | D8: 0 | E8: No matching concept | F8: 18.607298 | G8: Uncategorised | H8: Mean of corresponding source specialties | I8: =B8-F8 -> -18.305973
A9: Availability Monitor | B9: =VLOOKUP(A9,source_cprd_aurum!$A$2:$H$158,8,FALSE) -> 0.30132536 | C9: =VLOOKUP(A9,source_cprd_aurum!$A$2:$F$158,6,FALSE) -> Admin | D9: 0 | E9: No matching concept | F9: 18.607298 | G9: Uncategorised | H9: Mean of corresponding source specialties | I9: =B9-F9 -> -18.305973
A10: Helpdesk Technician | B10: =VLOOKUP(A10,source_cprd_aurum!$A$2:$H$158,8,FALSE) -> 0.30132536 | C10: =VLOOKUP(A10,source_cprd_aurum!$A$2:$F$158,6,FALSE) -> Admin | D10: 0 | E10: No matching concept | F10: 18.607298 | G10: Uncategorised | H10: Mean of corresponding source specialties | I10: =B10-F10 -> -18.305973
A11: Information Officer | B11: =VLOOKUP(A11,source_cprd_aurum!$A$2:$H$158,8,FALSE) -> 0.30132536 | C11: =VLOOKUP(A11,source_cprd_aurum!$A$2:$F$158,6,FALSE) -> Admin | D11: 0 | E11: No matching concept | F11: 18.607298 | G11: Uncategorised | H11: Mean of corresponding source specialties | I11: =B11-F11 -> -18.305973
A12: Medical Records Manager | B12: =VLOOKUP(A12,source_cprd_aurum!$A$2:$H$158,8,FALSE) -> 0.30132536 | C12: =VLOOKUP(A12,source_cprd_aurum!$A$2:$F$158,6,FALSE) -> Admin | D12: 0 | E12: No matching concept | F12: 18.607298 | G12: Uncategorised | H12: Mean of corresponding source specialties | I12: =B12-F12 -> -18.305973
A13: Network Technician | B13: =VLOOKUP(A13,source_cprd_aurum!$A$2:$H$158,8,FALSE) -> 0.30132536 | C13: =VLOOKUP(A13,source_cprd_aurum!$A$2:$F$158,6,FALSE) -> Admin | D13: 0 | E13: No matching concept | F13: 18.607298 | G13: Uncategorised | H13: Mean of corresponding source specialties | I13: =B13-F13 -> -18.305973
... A157: Radiologist | B157: =VLOOKUP(A157,source_cprd_aurum!$A$2:$H$158,8,FALSE) -> 74 | C157: =VLOOKUP(A157,source_cprd_aurum!$A$2:$F$158,6,FALSE) -> AHP | D157: 0 | E157: No matching concept | F157: 18.607298 | G157: Uncategorised | H157: Mean of corresponding source specialties | I157: =B157-F157 -> 55.392702

Sheet notes
D2: I derived a list of specialties for each datasets for the visits in the study period
D4: Code used for extraction (Source-cprd) | O4: Code used for extraction (OMOP)
D7: validation_staff <- my_dm$`validation_staff` %>% collect() | O7: visit_data_study_period <- cdm$visit_detail %>%
D8: validation_consultation <- my_dm$`validation_consultation` %>% collect() %>% | O8: # Filter for only primary care visits
D9: # Filter such that we have the visits between the study start and study end dates | O9: dplyr::filter(visit_detail_concept_id == 581477) %>%
D10: filter(consdate >= study_start_date & consdate <= study_end_date) | O10: dplyr::inner_join(cdm$provider) %>%
O11: dplyr::filter(visit_detail_start_date >= study_start_date & # include only visits in the study period
O12: visit_detail_start_date <= study_end_date) %>% compute()
D13: visit_data_study_period <- inner_join (validation_consultation, validation_staff ,
D14: by = "staffid")
O15: specialty_freq <- visit_data_study_period %>%
D16: specialty_freq <- visit_data_study_period %>% | O16: group_by(specialty_concept_id) %>%
D17: count(description) %>% | O17: summarise(n = n()) %>%
D18: mutate( | O18: mutate(percent = round(100 * n / sum(n), 1)) %>%
D19: percent = round(100 * n / sum(n), 1) | O19: left_join(cdm$concept, by = c("specialty_concept_id" = "concept_id")) %>%
D20: ) %>% | O20: select(specialty_concept_id, concept_name, n, percent) %>%
D21: arrange(desc(n)) | O21: arrange(desc(n)) %>%
O22: collect()
D23: library(rio)
D24: export(specialty_freq, "specialty_frequency_whole_cprd_source_study_period.xlsx")
D27: Assumptions
D28: Costing was performed using the specialty categories from the source CPRD data, with unit values listed in the source_cprd sheet.
D29: OMOP specialty_concept_ids were assigned costs based on their corresponding CPRD specialties.
D30: When multiple CPRD specialties mapped to the same concept ID, an average cost was used.
D31: For source specialties that could not be mapped to a concept ID (i.e., unmatched), an average of all CPRD specialty costs was applied.
D32: In the master sheet there are values for source and omop side to side
